<?xml version="1.0"?>
<robot name="dobot"  
       xmlns:gazebo="http://playerstage.sourceforge.net/gazebo/xmlschema/#gz"  
       xmlns:model="http://playerstage.sourceforge.net/gazebo/xmlschema/#model"  
       xmlns:sensor="http://playerstage.sourceforge.net/gazebo/xmlschema/#sensor"  
       xmlns:body="http://playerstage.sourceforge.net/gazebo/xmlschema/#body"  
       xmlns:geom="http://playerstage.sourceforge.net/gazebo/xmlschema/#geom"  
       xmlns:joint="http://playerstage.sourceforge.net/gazebo/xmlschema/#joint"  
       xmlns:interface="http://playerstage.sourceforge.net/gazebo/xmlschema/#interface"  
       xmlns:rendering="http://playerstage.sourceforge.net/gazebo/xmlschema/#rendering"  
       xmlns:renderable="http://playerstage.sourceforge.net/gazebo/xmlschema/#renderable"  
       xmlns:controller="http://playerstage.sourceforge.net/gazebo/xmlschema/#controller"  
       xmlns:physics="http://playerstage.sourceforge.net/gazebo/xmlschema/#physics">

  <property name="PI" value="3.1415926535897931" /> 
  <property name="joint12_degree" value="0" /> 
  <property name="joint23_degree" value="0" />
  <property name="joint34_degree" value="90" />
  
  

  <material name="blue">
    <color rgba="0 0 1 1"/>
  </material>
  <material name="green">
    <color rgba="0 1 0 1"/>
  </material>
  <material name="red">
    <color rgba="1 0 0 1"/>
  </material>
  <material name="white">
    <color rgba="1 1 1 1"/>
  </material>
  <material name="yellow">
    <color rgba="1 1 0 1"/>
  </material>


  <link name="base_link" >
    <visual>
       <geometry>
	  <box size="0.16 0.16 0.056"/> //base is 0.16*0.16*0.056
       </geometry>
       <material name="blue"/>
    </visual>
  </link>

  <link name="link2" >
    <visual>
       <geometry>
	  <cylinder radius="0.07" length="0.08"/> //link2 is radius 0.07 and height 0.08
       </geometry>
       <origin xyz="0 0 0.04" rpy="0 0 0"/> //link2 z + 1/2 h_itself
       <material name="green"/>
    </visual>
  </link>

  <link name="link3" >
    <visual>
       <geometry>
	  <box size="0.07 0.04 0.14"/> //link3 is 0.07*0.04*0.14
       </geometry>
       <origin xyz="-0.035 0 0.07" rpy="0 0 0"/> //link3 z + 1/2 h_itself, x - 1/2 l_itself
       <material name="red"/>
    </visual>
  </link>

  <link name="link4" >
    <visual>
       <geometry>
	  <box size="0.07 0.04 0.14"/> //link4 is 0.07*0.04*0.14
       </geometry>
       <origin xyz="-0.035 0 0.07" rpy="0 0 0"/> //link4 z + 1/2 h_itself, x - 1/2 l_itself
       <material name="white"/>
    </visual>
  </link>

  <link name="link5" >
    <visual>
       <geometry>
	  <box size="0.09 0.05 0.07"/> //link5 is 0.09*0.05*0.07
       </geometry>
       <origin xyz="0.045 0 -0.035" rpy="0 0 0"/> //link5 z + 1/2 h_itself, x - 1/2 l_itself
       <material name="yellow"/>
    </visual>
  </link>

  <joint name="joint12" type="continuous">
    <axis xyz="0 0 1"/>
    <parent link="base_link"/>
    <child link="link2"/>
    <origin xyz="0 0 0.028" rpy="0 0 ${joint12_degree/180*PI}" /> //joint12 z + 1/2 h_parent; rpy z is the rotate angle
  </joint>

  <joint name="joint23" type="continuous">
    <axis xyz="0 1 0"/>
    <parent link="link2"/>
    <child link="link3"/>
    <origin xyz="0 0 0.08" rpy="0 ${joint23_degree/180*PI} 0" /> //joint23 z + h_parent;  rpy y is the rotate angle
  </joint>

  <joint name="joint34" type="continuous">
    <axis xyz="0 1 0"/>
    <parent link="link3"/>
    <child link="link4"/>
    <origin xyz="0 0 0.14" rpy="0 ${joint34_degree/180*PI} 0" /> //joint34 z + h_parent; rpy y is the rotate angle
  </joint>

  <joint name="joint45" type="continuous">
    <axis xyz="0 1 0"/>
    <parent link="link4"/>
    <child link="link5"/>
    <origin xyz="0 0 0.14" rpy="0 -${(joint23_degree+joint34_degree)/180*PI} 0" /> //joint34 ; rpy y is the rotate angle
  </joint>

</robot>
